Workbook

Sheet Equal Weights Portfolio
C1: CLOSING PRICES | I1: DAILY RETURNS
B2: SBIN.NS | C2: TATASTEEL.NS | H2: RSBIN | I2: RTATASTEEL
A3: Date | B3: Close | C3: Close | H3: RETURNS | I3: RETURNS
A4: 13-04-2022 | B4: 517.7 | C4: 131.95 | M4: Returns | N4: Weights | P4: WR
A5: 18-04-2022 | B5: 509.5 | C5: 133.91 | H5: =LN(B5/B4) -> -0.015966071 | I5: =LN(C5/C4) -> 0.01474487 | M5: 0.020780948 | N5: 0.5 | P5: =N5*M5 -> 0.010390474
A6: 19-04-2022 | B6: 511.8 | C6: 132.66 | H6: =LN(B6/B5) -> 0.0045040711 | I6: =LN(C6/C5) -> -0.0093784684 | M6: -0.18865733 | N6: 0.5 | P6: =N6*M6 -> -0.094328663
A7: 20-04-2022 | B7: 509.3 | C7: 131.425 | H7: =LN(B7/B6) -> -0.0048966898 | I7: =LN(C7/C6) -> -0.0093531174 | N7: 1
A8: 21-04-2022 | B8: 516.3 | C8: 130.215 | H8: =LN(B8/B7) -> 0.013650758 | I8: =LN(C8/C7) -> -0.0092494162
A9: 22-04-2022 | B9: 500.6 | C9: 127.755 | H9: =LN(B9/B8) -> -0.030880613 | I9: =LN(C9/C8) -> -0.019072563 | O9: Portfolio Return | P9: =SUM(P5:P6) -> -0.083938189
A10: 25-04-2022 | B10: 494.75 | C10: 122.035 | H10: =LN(B10/B9) -> -0.011754795 | I10: =LN(C10/C9) -> -0.045806478
A11: 26-04-2022 | B11: 505.5 | C11: 123.36 | H11: =LN(B11/B10) -> 0.021495454 | I11: =LN(C11/C10) -> 0.010799021 | O11: rf | P11: 0.07
A12: 27-04-2022 | B12: 497.25 | C12: 124.67 | H12: =LN(B12/B11) -> -0.016455121 | I12: =LN(C12/C11) -> 0.010563337
A13: 28-04-2022 | B13: 507.5 | C13: 126.085 | H13: =LN(B13/B12) -> 0.020403793 | I13: =LN(C13/C12) -> 0.011286036 | O13: PV | P13: {=MMULT(TRANSPOSE(N5:N6),MMULT(P17:Q18,N5:N6))} -> 0.00025792207
A14: 29-04-2022 | B14: 496.3 | C14: 127.105 | H14: =LN(B14/B13) -> -0.022316128 | I14: =LN(C14/C13) -> 0.0080572338 | O14: PSD | P14: =SQRT(P13) -> 0.016059952
A15: 44597 | B15: 491 | C15: 129.52 | H15: =LN(B15/B14) -> -0.010736455 | I15: =LN(C15/C14) -> 0.018821793 | O15: ASD | P15: =SQRT(252)*P14 -> 0.25494384
A16: 44656 | B16: 479.65 | C16: 126.135 | H16: =LN(B16/B15) -> -0.023387457 | I16: =LN(C16/C15) -> -0.026482547 | P16: RSBIN | Q16: RTATASTEEEL
A17: 44686 | B17: 480 | C17: 128.425 | H17: =LN(B17/B16) -> 0.00072943264 | I17: =LN(C17/C16) -> 0.017992314 | O17: RSBIN | P17: =VARP('Equal Weights Portfolio'!$H$5:$H$250) -> 0.00024729241 | Q17: 0.00013557286
A18: 44717 | B18: 483.95 | C18: 128.37 | H18: =LN(B18/B17) -> 0.0081954917 | I18: =LN(C18/C17) -> -0.00042835726 | O18: RTATASTEEL | P18: 0.00013557286 | Q18: =VARP('Equal Weights Portfolio'!$I$5:$I$250) -> 0.00051325017
A19: 44809 | B19: 475.9 | C19: 125.225 | H19: =LN(B19/B18) -> -0.016773847 | I19: =LN(C19/C18) -> -0.0248046
A20: 44839 | B20: 475.2 | C20: 116.49 | H20: =LN(B20/B19) -> -0.0014719801 | I20: =LN(C20/C19) -> -0.072306687 | O20: Sharpe Ratio | P20: =(P9-P11)/P15 -> -0.60381215
A21: 44870 | B21: 476.55 | C21: 116.57 | H21: =LN(B21/B20) -> 0.0028368813 | I21: =LN(C21/C20) -> 0.00068651852
A22: 44900 | B22: 462.65 | C22: 111.77 | H22: =LN(B22/B21) -> -0.029601821 | I22: =LN(C22/C21) -> -0.042048763
A23: 13-05-2022 | B23: 444.65 | C23: 109.7 | H23: =LN(B23/B22) -> -0.039683373 | I23: =LN(C23/C22) -> -0.018693821
A24: 16-05-2022 | B24: 455 | C24: 110.35 | H24: =LN(B24/B23) -> 0.023009963 | I24: =LN(C24/C23) -> 0.0059077654
A25: 17-05-2022 | B25: 467.3 | C25: 118.87 | H25: =LN(B25/B24) -> 0.026674031 | I25: =LN(C25/C24) -> 0.074373326
A26: 18-05-2022 | B26: 458 | C26: 118.025 | H26: =LN(B26/B25) -> -0.020102266 | I26: =LN(C26/C25) -> -0.0071339926
A27: 19-05-2022 | B27: 447.5 | C27: 112.215 | H27: =LN(B27/B26) -> -0.023192646 | I27: =LN(C27/C26) -> -0.050479792
A28: 20-05-2022 | B28: 462.4 | C28: 117.06 | H28: =LN(B28/B27) -> 0.03275378 | I28: =LN(C28/C27) -> 0.04226995
A29: 23-05-2022 | B29: 460.9 | C29: 102.295 | H29: =LN(B29/B28) -> -0.0032492176 | I29: =LN(C29/C28) -> -0.13482583
A30: 24-05-2022 | B30: 462.05 | C30: 100.635 | H30: =LN(B30/B29) -> 0.0024920106 | I30: =LN(C30/C29) -> -0.016360686
A31: 25-05-2022 | B31: 454.1 | C31: 99.91 | H31: =LN(B31/B30) -> -0.017355672 | I31: =LN(C31/C30) -> -0.0072303289
A32: 26-05-2022 | B32: 468.9 | C32: 105.2 | H32: =LN(B32/B31) -> 0.032072088 | I32: =LN(C32/C31) -> 0.05159352
A33: 27-05-2022 | B33: 468.95 | C33: 104.35 | H33: =LN(B33/B32) -> 0.00010662686 | I33: =LN(C33/C32) -> -0.0081126668
A34: 30-05-2022 | B34: 474.6 | C34: 104.745 | H34: =LN(B34/B33) -> 0.011976191 | I34: =LN(C34/C33) -> 0.0037781914
A35: 31-05-2022 | B35: 468.1 | C35: 105.565 | H35: =LN(B35/B34) -> -0.013790396 | I35: =LN(C35/C34) -> 0.007798052
A36: 44567 | B36: 468.3 | C36: 106.355 | H36: =LN(B36/B35) -> 0.00042716788 | I36: =LN(C36/C35) -> 0.0074556782
A37: 44598 | B37: 469.85 | C37: 108.155 | H37: =LN(B37/B36) -> 0.0033043786 | I37: =LN(C37/C36) -> 0.016782828
A38: 44626 | B38: 464.5 | C38: 106.73 | H38: =LN(B38/B37) -> -0.011451937 | I38: =LN(C38/C37) -> -0.013263102
A39: 44718 | B39: 463.7 | C39: 107.81 | H39: =LN(B39/B38) -> -0.0017237669 | I39: =LN(C39/C38) -> 0.010068138
A40: 44748 | B40: 463.4 | C40: 106.85 | H40: =LN(B40/B39) -> -0.0006471794 | I40: =LN(C40/C39) -> -0.0089444368
...

Sheet Opimal P
C1: CLOSING PRICES | I1: DAILY RETURNS
B2: SBIN.NS | C2: TATASTEEL.NS | H2: RSBIN | I2: RTATASTEEL
A3: Date | B3: Close | C3: Close | H3: RETURNS | I3: RETURNS
A4: 13-04-2022 | B4: 517.7 | C4: 131.95 | M4: Returns | N4: Weights | P4: WR
A5: 18-04-2022 | B5: 509.5 | C5: 133.91 | H5: =LN(B5/B4) -> -0.015966071 | I5: =LN(C5/C4) -> 0.01474487 | M5: 0.020780948 | N5: 1 | P5: =N5*M5 -> 0.020780948
A6: 19-04-2022 | B6: 511.8 | C6: 132.66 | H6: =LN(B6/B5) -> 0.0045040711 | I6: =LN(C6/C5) -> -0.0093784684 | M6: -0.18865733 | N6: 0 | P6: =N6*M6 -> 0
A7: 20-04-2022 | B7: 509.3 | C7: 131.425 | H7: =LN(B7/B6) -> -0.0048966898 | I7: =LN(C7/C6) -> -0.0093531174 | N7: =SUM(N5:N6) -> 1
A8: 21-04-2022 | B8: 516.3 | C8: 130.215 | H8: =LN(B8/B7) -> 0.013650758 | I8: =LN(C8/C7) -> -0.0092494162
A9: 22-04-2022 | B9: 500.6 | C9: 127.755 | H9: =LN(B9/B8) -> -0.030880613 | I9: =LN(C9/C8) -> -0.019072563 | O9: Portfolio Return | P9: =SUM(P5:P6) -> 0.020780948
A10: 25-04-2022 | B10: 494.75 | C10: 122.035 | H10: =LN(B10/B9) -> -0.011754795 | I10: =LN(C10/C9) -> -0.045806478
A11: 26-04-2022 | B11: 505.5 | C11: 123.36 | H11: =LN(B11/B10) -> 0.021495454 | I11: =LN(C11/C10) -> 0.010799021 | O11: rf | P11: 0.07
A12: 27-04-2022 | B12: 497.25 | C12: 124.67 | H12: =LN(B12/B11) -> -0.016455121 | I12: =LN(C12/C11) -> 0.010563337
A13: 28-04-2022 | B13: 507.5 | C13: 126.085 | H13: =LN(B13/B12) -> 0.020403793 | I13: =LN(C13/C12) -> 0.011286036 | O13: PV | P13: {=MMULT(TRANSPOSE(N5:N6),MMULT(P17:Q18,N5:N6))} -> 0.00024729241
A14: 29-04-2022 | B14: 496.3 | C14: 127.105 | H14: =LN(B14/B13) -> -0.022316128 | I14: =LN(C14/C13) -> 0.0080572338 | O14: PSD | P14: =SQRT(P13) -> 0.015725534
A15: 44597 | B15: 491 | C15: 129.52 | H15: =LN(B15/B14) -> -0.010736455 | I15: =LN(C15/C14) -> 0.018821793 | O15: ASD | P15: =SQRT(252)*P14 -> 0.24963511
A16: 44656 | B16: 479.65 | C16: 126.135 | H16: =LN(B16/B15) -> -0.023387457 | I16: =LN(C16/C15) -> -0.026482547 | P16: RSBIN | Q16: RTATASTEEEL
A17: 44686 | B17: 480 | C17: 128.425 | H17: =LN(B17/B16) -> 0.00072943264 | I17: =LN(C17/C16) -> 0.017992314 | O17: RSBIN | P17: =VARP('Opimal P'!$H$5:$H$250) -> 0.00024729241 | Q17: 0.00013557286
A18: 44717 | B18: 483.95 | C18: 128.37 | H18: =LN(B18/B17) -> 0.0081954917 | I18: =LN(C18/C17) -> -0.00042835726 | O18: RTATASTEEL | P18: 0.00013557286 | Q18: =VARP('Opimal P'!$I$5:$I$250) -> 0.00051325017
A19: 44809 | B19: 475.9 | C19: 125.225 | H19: =LN(B19/B18) -> -0.016773847 | I19: =LN(C19/C18) -> -0.0248046
A20: 44839 | B20: 475.2 | C20: 116.49 | H20: =LN(B20/B19) -> -0.0014719801 | I20: =LN(C20/C19) -> -0.072306687 | O20: Sharpe Ratio | P20: =(P9-P11)/P15 -> -0.19716398
A21: 44870 | B21: 476.55 | C21: 116.57 | H21: =LN(B21/B20) -> 0.0028368813 | I21: =LN(C21/C20) -> 0.00068651852
A22: 44900 | B22: 462.65 | C22: 111.77 | H22: =LN(B22/B21) -> -0.029601821 | I22: =LN(C22/C21) -> -0.042048763
A23: 13-05-2022 | B23: 444.65 | C23: 109.7 | H23: =LN(B23/B22) -> -0.039683373 | I23: =LN(C23/C22) -> -0.018693821
A24: 16-05-2022 | B24: 455 | C24: 110.35 | H24: =LN(B24/B23) -> 0.023009963 | I24: =LN(C24/C23) -> 0.0059077654
A25: 17-05-2022 | B25: 467.3 | C25: 118.87 | H25: =LN(B25/B24) -> 0.026674031 | I25: =LN(C25/C24) -> 0.074373326
A26: 18-05-2022 | B26: 458 | C26: 118.025 | H26: =LN(B26/B25) -> -0.020102266 | I26: =LN(C26/C25) -> -0.0071339926
A27: 19-05-2022 | B27: 447.5 | C27: 112.215 | H27: =LN(B27/B26) -> -0.023192646 | I27: =LN(C27/C26) -> -0.050479792
A28: 20-05-2022 | B28: 462.4 | C28: 117.06 | H28: =LN(B28/B27) -> 0.03275378 | I28: =LN(C28/C27) -> 0.04226995
A29: 23-05-2022 | B29: 460.9 | C29: 102.295 | H29: =LN(B29/B28) -> -0.0032492176 | I29: =LN(C29/C28) -> -0.13482583
A30: 24-05-2022 | B30: 462.05 | C30: 100.635 | H30: =LN(B30/B29) -> 0.0024920106 | I30: =LN(C30/C29) -> -0.016360686
A31: 25-05-2022 | B31: 454.1 | C31: 99.91 | H31: =LN(B31/B30) -> -0.017355672 | I31: =LN(C31/C30) -> -0.0072303289
A32: 26-05-2022 | B32: 468.9 | C32: 105.2 | H32: =LN(B32/B31) -> 0.032072088 | I32: =LN(C32/C31) -> 0.05159352
A33: 27-05-2022 | B33: 468.95 | C33: 104.35 | H33: =LN(B33/B32) -> 0.00010662686 | I33: =LN(C33/C32) -> -0.0081126668
A34: 30-05-2022 | B34: 474.6 | C34: 104.745 | H34: =LN(B34/B33) -> 0.011976191 | I34: =LN(C34/C33) -> 0.0037781914
A35: 31-05-2022 | B35: 468.1 | C35: 105.565 | H35: =LN(B35/B34) -> -0.013790396 | I35: =LN(C35/C34) -> 0.007798052
A36: 44567 | B36: 468.3 | C36: 106.355 | H36: =LN(B36/B35) -> 0.00042716788 | I36: =LN(C36/C35) -> 0.0074556782
A37: 44598 | B37: 469.85 | C37: 108.155 | H37: =LN(B37/B36) -> 0.0033043786 | I37: =LN(C37/C36) -> 0.016782828
A38: 44626 | B38: 464.5 | C38: 106.73 | H38: =LN(B38/B37) -> -0.011451937 | I38: =LN(C38/C37) -> -0.013263102
A39: 44718 | B39: 463.7 | C39: 107.81 | H39: =LN(B39/B38) -> -0.0017237669 | I39: =LN(C39/C38) -> 0.010068138
A40: 44748 | B40: 463.4 | C40: 106.85 | H40: =LN(B40/B39) -> -0.0006471794 | I40: =LN(C40/C39) -> -0.0089444368
...

Sheet backtest stocks
B2: SBIN | C2: TATASTEEL | F2: RSBIN | G2: RTATASTEEL
A3: Date | B3: Close | C3: Close
A4: 45033 | B4: 544 | C4: 107.5
A5: 45034 | B5: 545.84998 | C5: 107.15 | F5: =LN(B5/B4) -> 0.0033949219 | G5: =LN(C5/C4) -> -0.003261107 | J5: Returns | K5: Weights | M5: WR
A6: 45035 | B6: 540.29999 | C6: 107.6 | F6: =LN(B6/B5) -> -0.01021965 | G6: =LN(C6/C5) -> 0.0041908886 | J6: =F251 -> 0.42419943 | K6: 1 | M6: =J6*K6 -> 0.42419943 | O6: The weights are from optimized portfolio
A7: 45036 | B7: 544.79999 | C7: 108.1 | F7: =LN(B7/B6) -> 0.0082942142 | G7: =LN(C7/C6) -> 0.004636077 | J7: =G251 -> 0.55647968 | K7: 0 | M7: =J7*K7 -> 0
A8: 45037 | B8: 543.15002 | C8: 108 | F8: =LN(B8/B7) -> -0.0030331637 | G8: =LN(C8/C7) -> -0.00092547902 | K8: =SUM(K6:K7) -> 1
A9: 45040 | B9: 554.59998 | C9: 106.15 | F9: =LN(B9/B8) -> 0.020861521 | G9: =LN(C9/C8) -> -0.01727802
A10: 45041 | B10: 561.79999 | C10: 106.5 | F10: =LN(B10/B9) -> 0.012898803 | G10: =LN(C10/C9) -> 0.0032917782 | L10: Portfolio Return | M10: =SUM(M6:M7) -> 0.42419943 | O10: better returns
A11: 45042 | B11: 566.34998 | C11: 107.05 | F11: =LN(B11/B10) -> 0.008066326 | G11: =LN(C11/C10) -> 0.0051510579
A12: 45043 | B12: 564.75 | C12: 106.85 | F12: =LN(B12/B11) -> -0.0028290639 | G12: =LN(C12/C11) -> -0.00187008 | L12: rf | M12: 0.07
A13: 45044 | B13: 578.29999 | C13: 107.65 | F13: =LN(B13/B12) -> 0.023709589 | G13: =LN(C13/C12) -> 0.0074592793
A14: 45048 | B14: 575.29999 | C14: 107.95 | F14: =LN(B14/B13) -> -0.0052011214 | G14: =LN(C14/C13) -> 0.0027828868 | L14: PV | M14: {=MMULT(TRANSPOSE(K6:K7),MMULT(M19:N20,K6:K7))} -> 0.00016722705 | O14: Lesser volatility
A15: 45049 | B15: 570.5 | C15: 110.3 | F15: =LN(B15/B14) -> -0.0083784537 | G15: =LN(C15/C14) -> 0.021535824 | L15: PSD | M15: =SQRT(M14) -> 0.01293163
A16: 45050 | B16: 580 | C16: 109.7 | F16: =LN(B16/B15) -> 0.016514934 | G16: =LN(C16/C15) -> -0.0054546135 | L16: ASD | M16: =SQRT(252)*M15 -> 0.20528326
A17: 45051 | B17: 576.5 | C17: 111.05 | F17: =LN(B17/B16) -> -0.0060527638 | G17: =LN(C17/C16) -> 0.012231237
A18: 45054 | B18: 583.59998 | C18: 108.65 | F18: =LN(B18/B17) -> 0.012240436 | G18: =LN(C18/C17) -> -0.021848852 | M18: SBIN | N18: TATASTEEL
A19: 45055 | B19: 573.5 | C19: 109.55 | F19: =LN(B19/B18) -> -0.017457839 | G19: =LN(C19/C18) -> 0.0082493683 | L19: SBIN | M19: =VARP('backtest stocks'!$F$5:$F$248) -> 0.00016722705 | N19: -1.6911503e-06
A20: 45056 | B20: 572.20001 | C20: 109.55 | F20: =LN(B20/B19) -> -0.002269335 | G20: =LN(C20/C19) -> 0 | L20: TATASTEEL | M20: -1.6911503e-06 | N20: =VARP('backtest stocks'!$G$5:$G$248) -> 0.00023176592
A21: 45057 | B21: 573.45001 | C21: 109.25 | F21: =LN(B21/B20) -> 0.0021821681 | G21: =LN(C21/C20) -> -0.0027422595
A22: 45058 | B22: 578.15002 | C22: 108.55 | F22: =LN(B22/B21) -> 0.0081626224 | G22: =LN(C22/C21) -> -0.00642791
A23: 45061 | B23: 581.90002 | C23: 106.75 | F23: =LN(B23/B22) -> 0.0064652608 | G23: =LN(C23/C22) -> -0.016721272 | L23: Sharpe Ratio | M23: =(M12-M14)/M16 -> 0.34017764 | O23: better sharpe ratio
A24: 45062 | B24: 586.29999 | C24: 107.7 | F24: =LN(B24/B23) -> 0.0075329306 | G24: =LN(C24/C23) -> 0.0088599042
A25: 45063 | B25: 586.29999 | C25: 107.4 | F25: =LN(B25/B24) -> 0 | G25: =LN(C25/C24) -> -0.0027893556
A26: 45064 | B26: 574.20001 | C26: 106 | F26: =LN(B26/B25) -> -0.020853795 | G26: =LN(C26/C25) -> -0.013121107
A27: 45065 | B27: 575.15002 | C27: 105.2 | F27: =LN(B27/B26) -> 0.0016531295 | G27: =LN(C27/C26) -> -0.0075758223
A28: 45068 | B28: 577.15002 | C28: 104.65 | F28: =LN(B28/B27) -> 0.0034713216 | G28: =LN(C28/C27) -> -0.0052418038
A29: 45069 | B29: 581.59998 | C29: 105 | F29: =LN(B29/B28) -> 0.0076806453 | G29: =LN(C29/C28) -> 0.0033388822
A30: 45070 | B30: 582.70001 | C30: 105.6 | F30: =LN(B30/B29) -> 0.0018896098 | G30: =LN(C30/C29) -> 0.0056980022
A31: 45071 | B31: 581.25 | C31: 105.2 | F31: =LN(B31/B30) -> -0.0024915378 | G31: =LN(C31/C30) -> -0.0037950805
A32: 45072 | B32: 586 | C32: 104.85 | F32: =LN(B32/B31) -> 0.0081388327 | G32: =LN(C32/C31) -> -0.0033325335
A33: 45075 | B33: 595 | C33: 106.4 | F33: =LN(B33/B32) -> 0.015241616 | G33: =LN(C33/C32) -> 0.014674857
A34: 45076 | B34: 592.79999 | C34: 108.45 | F34: =LN(B34/B33) -> -0.0037043518 | G34: =LN(C34/C33) -> 0.019083614
A35: 45077 | B35: 579.84998 | C35: 107.05 | F35: =LN(B35/B34) -> -0.022087646 | G35: =LN(C35/C34) -> -0.012993167
... A248: 45394 | B248: 766.29999 | C248: 165.05 | F248: =LN(B248/B247) -> -0.016501491 | G248: =LN(C248/C247) -> -0.0057393119
E250: Daily returns | F250: =AVERAGE(F3:F248) -> 0.0014041987 | G250: =AVERAGE(G5:G248) -> 0.0017572034
E251: annualized returns | F251: =(1+F250)^252-1 -> 0.42419943 | G251: =(1+G250)^252-1 -> 0.55647968

Sheet EQUAL WEIGHTS INDICES
A1: Date | B1: CLOSING ON NIFTY50 | C1: CLOSING ON S&P500 | F1: RETURNS ON NIFTY50 | G1: RETURNS ON S&P500
A2: 44669 | B2: 17173.65 | C2: 4392.5898 | F2: ~ | G2: ~
A3: 44670 | B3: 16958.65 | C3: 4391.6899 | F3: =LN(B3/B2) -> -0.012598204 | G3: =LN(C3/C2) -> -0.00020488942
A4: 44671 | B4: 17136.551 | C4: 4462.21 | F4: =LN(B4/B3) -> 0.010435604 | G4: =LN(C4/C3) -> 0.015930045
A5: 44672 | B5: 17392.6 | C5: 4459.4502 | F5: =LN(B5/B4) -> 0.014831151 | G5: =LN(C5/C4) -> -0.00061866649
A6: 44673 | B6: 17171.949 | C6: 4393.6602 | F6: =LN(B6/B5) -> -0.012767613 | G6: =LN(C6/C5) -> -0.014862856 | J6: R | K6: W | L6: RW
A7: 44676 | B7: 16953.949 | C7: 4271.7798 | F7: =LN(B7/B6) -> -0.012776394 | G7: =LN(C7/C6) -> -0.028132076 | J7: 0.039046159 | K7: 0.5 | L7: =K7*J7 -> 0.01952308
A8: 44677 | B8: 17200.801 | C8: 4296.1201 | F8: =LN(B8/B7) -> 0.014455141 | G8: =LN(C8/C7) -> 0.0056817651 | J8: -0.0660655 | K8: 0.5 | L8: =K8*J8 -> -0.03303275
A9: 44678 | B9: 17038.4 | C9: 4175.2002 | F9: =LN(B9/B8) -> -0.0094862965 | G9: =LN(C9/C8) -> -0.028550009 | K9: =SUM(K7:K8) -> 1
A10: 44679 | B10: 17245.051 | C10: 4183.96 | F10: =LN(B10/B9) -> 0.012055548 | G10: =LN(C10/C9) -> 0.0020958491
A11: 44680 | B11: 17102.551 | C11: 4287.5 | F11: =LN(B11/B10) -> -0.0082975702 | G11: =LN(C11/C10) -> 0.024445655
A12: 44683 | B12: 17069.1 | C12: 4131.9302 | F12: =LN(B12/B11) -> -0.0019578324 | G12: =LN(C12/C11) -> -0.03695916 | J12: PR | K12: =SUM(L7:L8) -> -0.013509671
A13: 44685 | B13: 16677.6 | C13: 4155.3799 | F13: =LN(B13/B12) -> -0.02320331 | G13: =LN(C13/C12) -> 0.0056591993 | J13: Rf | K13: 0.07
A14: 44686 | B14: 16682.65 | C14: 4175.48 | F14: =LN(B14/B13) -> 0.00030280241 | G14: =LN(C14/C13) -> 0.0048254649
A15: 44687 | B15: 16411.25 | C15: 4300.1699 | F15: =LN(B15/B14) -> -0.016402205 | G15: =LN(C15/C14) -> 0.029425222 | J15: PSD | K15: {=SQRT(MMULT(TRANSPOSE(K7:K8),MMULT(K20:L21,K7:K8)))} -> 0.0093831467
A16: 44690 | B16: 16301.85 | C16: 4146.8701 | F16: =LN(B16/B15) -> -0.0066885009 | G16: =LN(C16/C15) -> -0.036300678 | J16: ASD | K16: =SQRT(252)*K15 -> 0.14895284
A17: 44691 | B17: 16240.05 | C17: 4123.3398 | F17: =LN(B17/B16) -> -0.0037981728 | G17: =LN(C17/C16) -> -0.0056903843
A18: 44692 | B18: 16167.1 | C18: 3991.24 | F18: =LN(B18/B17) -> -0.0045021127 | G18: =LN(C18/C17) -> -0.03256152
A19: 44693 | B19: 15808 | C19: 4001.05 | F19: =LN(B19/B18) -> -0.022462148 | G19: =LN(C19/C18) -> 0.0024548819 | K19: NIFTY50 | L19: S&P500
A20: 44694 | B20: 15782.15 | C20: 3935.1799 | F20: =LN(B20/B19) -> -0.0016365617 | G20: =LN(C20/C19) -> -0.016600232 | J20: NIFTY50 | K20: =VARP('EQUAL WEIGHTS INDICES'!$F$3:$F$248) -> 8.2458805e-05 | L20: 2.7043661e-05
A21: 44697 | B21: 15842.3 | C21: 3930.0801 | F21: =LN(B21/B20) -> 0.0038039862 | G21: =LN(C21/C20) -> -0.0012968051 | J21: S&P500 | K21: 2.7043661e-05 | L21: =VARP('EQUAL WEIGHTS INDICES'!$G$3:$G$248) -> 0.00021562764
A22: 44698 | B22: 16259.3 | C22: 4023.8899 | F22: =LN(B22/B21) -> 0.025981475 | G22: =LN(C22/C21) -> 0.023589268
A23: 44699 | B23: 16240.3 | C23: 4008.01 | F23: =LN(B23/B22) -> -0.0011692453 | G23: =LN(C23/C22) -> -0.0039542086
A24: 44700 | B24: 15809.4 | C24: 4088.8501 | F24: =LN(B24/B23) -> -0.026891071 | G24: =LN(C24/C23) -> 0.01996892 | J24: SR | K24: =(K12-K13)/K16 -> -0.56064505
A25: 44701 | B25: 16266.15 | C25: 3923.6799 | F25: =LN(B25/B24) -> 0.028481561 | G25: =LN(C25/C24) -> -0.041233809
A26: 44704 | B26: 16214.7 | C26: 3900.79 | F26: =LN(B26/B25) -> -0.0031680352 | G26: =LN(C26/C25) -> -0.0058508649
A27: 44705 | B27: 16125.15 | C27: 3901.3601 | F27: =LN(B27/B26) -> -0.005538061 | G27: =LN(C27/C26) -> 0.000146131
A28: 44706 | B28: 16025.8 | C28: 3973.75 | F28: =LN(B28/B27) -> -0.0061802778 | G28: =LN(C28/C27) -> 0.018384996
A29: 44707 | B29: 16170.15 | C29: 3941.48 | F29: =LN(B29/B28) -> 0.0089670628 | G29: =LN(C29/C28) -> -0.008153951
A30: 44708 | B30: 16352.45 | C30: 3978.73 | F30: =LN(B30/B29) -> 0.011210771 | G30: =LN(C30/C29) -> 0.0094063857
A31: 44711 | B31: 16661.4 | C31: 4057.8401 | F31: =LN(B31/B30) -> 0.018716945 | G31: =LN(C31/C30) -> 0.019688166
A32: 44712 | B32: 16584.551 | C32: 4158.2402 | F32: =LN(B32/B31) -> -0.0046231041 | G32: =LN(C32/C31) -> 0.02444113
A33: 44713 | B33: 16522.75 | C33: 4132.1499 | F33: =LN(B33/B32) -> -0.003733367 | G33: =LN(C33/C32) -> -0.0062941352
A34: 44714 | B34: 16628 | C34: 4101.23 | F34: =LN(B34/B33) -> 0.0063498023 | G34: =LN(C34/C33) -> -0.0075109051
A35: 44715 | B35: 16584.301 | C35: 4176.8198 | F35: =LN(B35/B34) -> -0.0026315096 | G35: =LN(C35/C34) -> 0.018263225
A36: 44718 | B36: 16569.551 | C36: 4108.54 | F36: =LN(B36/B35) -> -0.0008897911 | G36: =LN(C36/C35) -> -0.016482406
... A248: 45029 | B248: 17828 | C248: 4109.1099 | F248: =LN(B248/B247) -> 0.00087538916 | G248: =LN(C248/C247) -> 0.00099580683
E251: DR | F251: =AVERAGE(F3:F248) -> 0.00015200813 | G251: =AVERAGE(G3:G248) -> -0.0002711893
E254: AR | F254: =(1+F251)^252-1 -> 0.039046159 | G254: =(1+G251)^252-1 -> -0.0660655

Sheet OPTIMAL WEIGHTS INDICES
A1: Date | B1: CLOSING ON NIFTY50 | C1: CLOSING ON S&P500 | F1: RETURNS ON NIFTY50 | G1: RETURNS ON S&P500
A2: 44669 | B2: 17173.65 | C2: 4392.5898 | F2: ~ | G2: ~
A3: 44670 | B3: 16958.65 | C3: 4391.6899 | F3: =LN(B3/B2) -> -0.012598204 | G3: =LN(C3/C2) -> -0.00020488942
A4: 44671 | B4: 17136.551 | C4: 4462.21 | F4: =LN(B4/B3) -> 0.010435604 | G4: =LN(C4/C3) -> 0.015930045
A5: 44672 | B5: 17392.6 | C5: 4459.4502 | F5: =LN(B5/B4) -> 0.014831151 | G5: =LN(C5/C4) -> -0.00061866649
A6: 44673 | B6: 17171.949 | C6: 4393.6602 | F6: =LN(B6/B5) -> -0.012767613 | G6: =LN(C6/C5) -> -0.014862856 | J6: R | K6: W | L6: RW
A7: 44676 | B7: 16953.949 | C7: 4271.7798 | F7: =LN(B7/B6) -> -0.012776394 | G7: =LN(C7/C6) -> -0.028132076 | J7: 0.039046159 | K7: 1 | L7: =K7*J7 -> 0.039046159
A8: 44677 | B8: 17200.801 | C8: 4296.1201 | F8: =LN(B8/B7) -> 0.014455141 | G8: =LN(C8/C7) -> 0.0056817651 | J8: -0.0660655 | K8: 0 | L8: =K8*J8 -> 0
A9: 44678 | B9: 17038.4 | C9: 4175.2002 | F9: =LN(B9/B8) -> -0.0094862965 | G9: =LN(C9/C8) -> -0.028550009 | K9: =SUM(K7:K8) -> 1
A10: 44679 | B10: 17245.051 | C10: 4183.96 | F10: =LN(B10/B9) -> 0.012055548 | G10: =LN(C10/C9) -> 0.0020958491
A11: 44680 | B11: 17102.551 | C11: 4287.5 | F11: =LN(B11/B10) -> -0.0082975702 | G11: =LN(C11/C10) -> 0.024445655
A12: 44683 | B12: 17069.1 | C12: 4131.9302 | F12: =LN(B12/B11) -> -0.0019578324 | G12: =LN(C12/C11) -> -0.03695916 | J12: PR | K12: =SUM(L7:L8) -> 0.039046159
A13: 44685 | B13: 16677.6 | C13: 4155.3799 | F13: =LN(B13/B12) -> -0.02320331 | G13: =LN(C13/C12) -> 0.0056591993 | J13: Rf | K13: 0.07
A14: 44686 | B14: 16682.65 | C14: 4175.48 | F14: =LN(B14/B13) -> 0.00030280241 | G14: =LN(C14/C13) -> 0.0048254649
A15: 44687 | B15: 16411.25 | C15: 4300.1699 | F15: =LN(B15/B14) -> -0.016402205 | G15: =LN(C15/C14) -> 0.029425222 | J15: PSD | K15: {=SQRT(MMULT(TRANSPOSE(K7:K8),MMULT(K20:L21,K7:K8)))} -> 0.009080683
A16: 44690 | B16: 16301.85 | C16: 4146.8701 | F16: =LN(B16/B15) -> -0.0066885009 | G16: =LN(C16/C15) -> -0.036300678 | J16: ASD | K16: =SQRT(252)*K15 -> 0.14415137
A17: 44691 | B17: 16240.05 | C17: 4123.3398 | F17: =LN(B17/B16) -> -0.0037981728 | G17: =LN(C17/C16) -> -0.0056903843
A18: 44692 | B18: 16167.1 | C18: 3991.24 | F18: =LN(B18/B17) -> -0.0045021127 | G18: =LN(C18/C17) -> -0.03256152
A19: 44693 | B19: 15808 | C19: 4001.05 | F19: =LN(B19/B18) -> -0.022462148 | G19: =LN(C19/C18) -> 0.0024548819 | K19: NIFTY50 | L19: S&P500
A20: 44694 | B20: 15782.15 | C20: 3935.1799 | F20: =LN(B20/B19) -> -0.0016365617 | G20: =LN(C20/C19) -> -0.016600232 | J20: NIFTY50 | K20: =VARP('OPTIMAL WEIGHTS INDICES'!$F$3:$F$248) -> 8.2458805e-05 | L20: 2.7043661e-05
A21: 44697 | B21: 15842.3 | C21: 3930.0801 | F21: =LN(B21/B20) -> 0.0038039862 | G21: =LN(C21/C20) -> -0.0012968051 | J21: S&P500 | K21: 2.7043661e-05 | L21: =VARP('OPTIMAL WEIGHTS INDICES'!$G$3:$G$248) -> 0.00021562764
A22: 44698 | B22: 16259.3 | C22: 4023.8899 | F22: =LN(B22/B21) -> 0.025981475 | G22: =LN(C22/C21) -> 0.023589268
A23: 44699 | B23: 16240.3 | C23: 4008.01 | F23: =LN(B23/B22) -> -0.0011692453 | G23: =LN(C23/C22) -> -0.0039542086
A24: 44700 | B24: 15809.4 | C24: 4088.8501 | F24: =LN(B24/B23) -> -0.026891071 | G24: =LN(C24/C23) -> 0.01996892 | J24: SR | K24: =(K12-K13)/K16 -> -0.2147315
A25: 44701 | B25: 16266.15 | C25: 3923.6799 | F25: =LN(B25/B24) -> 0.028481561 | G25: =LN(C25/C24) -> -0.041233809
A26: 44704 | B26: 16214.7 | C26: 3900.79 | F26: =LN(B26/B25) -> -0.0031680352 | G26: =LN(C26/C25) -> -0.0058508649
A27: 44705 | B27: 16125.15 | C27: 3901.3601 | F27: =LN(B27/B26) -> -0.005538061 | G27: =LN(C27/C26) -> 0.000146131
A28: 44706 | B28: 16025.8 | C28: 3973.75 | F28: =LN(B28/B27) -> -0.0061802778 | G28: =LN(C28/C27) -> 0.018384996
A29: 44707 | B29: 16170.15 | C29: 3941.48 | F29: =LN(B29/B28) -> 0.0089670628 | G29: =LN(C29/C28) -> -0.008153951
A30: 44708 | B30: 16352.45 | C30: 3978.73 | F30: =LN(B30/B29) -> 0.011210771 | G30: =LN(C30/C29) -> 0.0094063857
A31: 44711 | B31: 16661.4 | C31: 4057.8401 | F31: =LN(B31/B30) -> 0.018716945 | G31: =LN(C31/C30) -> 0.019688166
A32: 44712 | B32: 16584.551 | C32: 4158.2402 | F32: =LN(B32/B31) -> -0.0046231041 | G32: =LN(C32/C31) -> 0.02444113
A33: 44713 | B33: 16522.75 | C33: 4132.1499 | F33: =LN(B33/B32) -> -0.003733367 | G33: =LN(C33/C32) -> -0.0062941352
A34: 44714 | B34: 16628 | C34: 4101.23 | F34: =LN(B34/B33) -> 0.0063498023 | G34: =LN(C34/C33) -> -0.0075109051
A35: 44715 | B35: 16584.301 | C35: 4176.8198 | F35: =LN(B35/B34) -> -0.0026315096 | G35: =LN(C35/C34) -> 0.018263225
A36: 44718 | B36: 16569.551 | C36: 4108.54 | F36: =LN(B36/B35) -> -0.0008897911 | G36: =LN(C36/C35) -> -0.016482406
... A248: 45029 | B248: 17828 | C248: 4109.1099 | F248: =LN(B248/B247) -> 0.00087538916 | G248: =LN(C248/C247) -> 0.00099580683
E251: DR | F251: =AVERAGE(F3:F248) -> 0.00015200813 | G251: =AVERAGE(G3:G248) -> -0.0002711893
E254: AR | F254: =(1+F251)^252-1 -> 0.039046159 | G254: =(1+G251)^252-1 -> -0.0660655

Sheet BACKTEST INDICES
A1: Date | B1: closing on nifty50 | C1: closing on s&p500 | E1: Return on nifty50 | F1: Reuturn on s&p500
A2: 45033 | B2: 17706.85 | C2: 4137.6401 | E2: ~ | F2: ~
A3: 45034 | B3: 17660.15 | C3: 4151.3198 | E3: -0.002640837 | F3: 0.003300703
A4: 45035 | B4: 17618.75 | C4: 4154.8701 | E4: -0.002347035 | F4: 0.000854855
A5: 45036 | B5: 17624.449 | C5: 4154.52 | E5: 0.000323422 | F5: -8.43e-05 | J5: R | K5: W | L5: RW
A6: 45037 | B6: 17624.051 | C6: 4129.79 | E6: -2.26e-05 | F6: -0.005970335 | I6: Return on nifty50 | J6: 0.28169854 | K6: 1 | L6: =K6*J6 -> 0.28169854
A7: 45040 | B7: 17743.4 | C7: 4133.52 | E7: 0.006749147 | F7: 0.000902781 | I7: Reuturn on s&p500 | J7: 0.2528071 | K7: 0 | L7: =K7*J7 -> 0
A8: 45041 | B8: 17769.25 | C8: 4137.04 | E8: 0.001455797 | F8: 0.000851217
A9: 45042 | B9: 17813.6 | C9: 4071.6299 | E9: 0.002492753 | F9: -0.015937184
A10: 45043 | B10: 17915.051 | C10: 4055.99 | E10: 0.005678997 | F10: -0.003848584 | J10: PR | K10: =SUM(L6+L7) -> 0.28169854 | M10: Rf | N10: 0.07
A11: 45044 | B11: 18065 | C11: 4135.3501 | E11: 0.008335179 | F11: 0.019377194
A12: 45048 | B12: 18147.65 | C12: 4169.48 | E12: 0.004564733 | F12: 0.008219331 | J12: PSD | K12: {=SQRT(MMULT(TRANSPOSE(K6:K7),MMULT(K16:L17,K6:K7)))} -> 0.0062209324
A13: 45049 | B13: 18089.85 | C13: 4167.8701 | E13: -0.003190111 | F13: -0.000386181 | J13: ASD | K13: =SQRT(252)*K12 -> 0.09875424
A14: 45050 | B14: 18255.801 | C14: 4119.5801 | E14: 0.009131895 | F14: -0.011653907
A15: 45051 | B15: 18069 | C15: 4090.75 | E15: -0.010285118 | F15: -0.007022908 | K15: NIFTY50 | L15: S&P500
A16: 45054 | B16: 18264.4 | C16: 4061.22 | E16: 0.010756069 | F16: -0.007244913 | J16: NIFTY50 | K16: 3.87e-05 | L16: 6.28e-06
A17: 45055 | B17: 18265.949 | C17: 4136.25 | E17: 8.48e-05 | F17: 0.018306166 | J17: S&P500 | K17: 6.28e-06 | L17: 5.31e-05
A18: 45056 | B18: 18315.1 | C18: 4138.1201 | E18: 0.002687207 | F18: 0.000452026
A19: 45057 | B19: 18297 | C19: 4119.1699 | E19: -0.000988723 | F19: -0.004589939
A20: 45058 | B20: 18314.801 | C20: 4137.6401 | E20: 0.000972407 | F20: 0.004473942 | J20: SR | K20: =(K10-N10)/K13 -> 2.1436906
A21: 45061 | B21: 18398.85 | C21: 4130.6201 | E21: 0.004578623 | F21: -0.001698065
A22: 45062 | B22: 18286.5 | C22: 4124.0801 | E22: -0.006125059 | F22: -0.001584562
A23: 45063 | B23: 18181.75 | C23: 4136.2798 | E23: -0.005744739 | F23: 0.002953798
A24: 45064 | B24: 18129.949 | C24: 4109.8999 | E24: -0.00285312 | F24: -0.006398108
A25: 45065 | B25: 18203.4 | C25: 4158.77 | E25: 0.004043187 | F25: 0.011820689
A26: 45068 | B26: 18314.4 | C26: 4198.0498 | E26: 0.006079246 | F26: 0.009400723
A27: 45069 | B27: 18348 | C27: 4191.98 | E27: 0.00183292 | F27: -0.001446914
A28: 45070 | B28: 18285.4 | C28: 4192.6299 | E28: -0.003417628 | F28: 0.000155023
A29: 45071 | B29: 18321.15 | C29: 4145.5801 | E29: 0.001953203 | F29: -0.011285469
A30: 45072 | B30: 18499.35 | C30: 4115.2402 | E30: 0.009679424 | F30: -0.007345513
A31: 45075 | B31: 18598.65 | C31: 4151.2798 | E31: 0.005353443 | F31: 0.008719456
A32: 45076 | B32: 18633.85 | C32: 4205.4502 | E32: 0.00189078 | F32: 0.012964681
... A246: 45394 | B246: 22519.4 | C246: 5147.21 | E246: -0.010355021 | F246: -0.012411036
D249: DR | E249: 0.000985351 | F249: 0.000894792
D252: AR | E252: 0.28169854 | F252: 0.2528071
